Workbook

Sheet Matriz_por_área
A1: Matriz didácticas × Área SWEBOK (agregada, sin subáreas) — leyenda de colores
A3: 1 | C3: 2 | E3: 3 a 5 | G3: 6 o más | I3: Fila extra (sin equivalente) / columna Sin área SWEBOK | L3: Encabezado de nivel/área
A5: Nivel taxonómico | B5: Técnica didáctica (código y nombre) | C5: REQUIREMENTS | D5: ARCHITECTURE | E5: DESIGN | F5: CONSTRUCTION | G5: SOFTWARE TESTING | H5: SOFTWARE ENG. OPERATIONS | I5: MAINTENANCE | J5: SOFTWARE CONFIG. MGMT. | K5: SOFTWARE ENG. PROCESS | L5: SOFTWARE ENG. MODELS/METH. | M5: SOFTWARE QUALITY | N5: SOFTWARE SECURITY | O5: PROFESSIONAL PRACTICE | P5: SOFTWARE ENG. ECONOMICS | Q5: SOFTWARE ENG. MANAGEMENT | R5: Sin área SWEBOK | S5: Total fila
A6: RECORDAR | B6: T001 Diario de aprendizaje | C6: =COUNTIFS('Prácticas_Revisiones'!$S$2:$S$282,"T001",'Prácticas_Revisiones'!$T$2:$T$282,"REQUIREMENTS > *")+COUNTIFS('Prácticas_Snowballing'!$AB$2:$AB$281,"T001",'Prácticas_Snowballing'!$AC$2:$AC$281,"REQUIREMENTS > *") -> 0 | D6: =COUNTIFS('Prácticas_Revisiones'!$S$2:$S$282,"T001",'Prácticas_Revisiones'!$T$2:$T$282,"ARCHITECTURE > *")+COUNTIFS('Prácticas_Snowballing'!$AB$2:$AB$281,"T001",'Prácticas_Snowballing'!$AC$2:$AC$281,"ARCHITECTURE > *") -> 0 | E6: =COUNTIFS('Prácticas_Revisiones'!$S$2:$S$282,"T001",'Prácticas_Revisiones'!$T$2:$T$282,"DESIGN > *")+COUNTIFS('Prácticas_Snowballing'!$AB$2:$AB$281,"T001",'Prácticas_Snowballing'!$AC$2:$AC$281,"DESIGN > *") -> 1 | F6: =COUNTIFS('Prácticas_Revisiones'!$S$2:$S$282,"T001",'Prácticas_Revisiones'!$T$2:$T$282,"CONSTRUCTION > *")+COUNTIFS('Prácticas_Snowballing'!$AB$2:$AB$281,"T001",'Prácticas_Snowballing'!$AC$2:$AC$281,"CONSTRUCTION > *") -> 5 | G6: =COUNTIFS('Prácticas_Revisiones'!$S$2:$S$282,"T001",'Prácticas_Revisiones'!$T$2:$T$282,"SOFTWARE TESTING > *")+COUNTIFS('Prácticas_Snowballing'!$AB$2:$AB$281,"T001",'Prácticas_Snowballing'!$AC$2:$AC$281,"SOFTWARE TESTING > *") -> 0 | H6: =COUNTIFS('Prácticas_Revisiones'!$S$2:$S$282,"T001",'Prácticas_Revisiones'!$T$2:$T$282,"SOFTWARE ENG. OPERATIONS > *")+COUNTIFS('Prácticas_Snowballing'!$AB$2:$AB$281,"T001",'Prácticas_Snowballing'!$AC$2:$AC$281,"SOFTWARE ENG. OPERATIONS > *") -> 0 | I6: =COUNTIFS('Prácticas_Revisiones'!$S$2:$S$282,"T001",'Prácticas_Revisiones'!$T$2:$T$282,"MAINTENANCE > *")+COUNTIFS('Prácticas_Snowballing'!$AB$2:$AB$281,"T001",'Prácticas_Snowballing'!$AC$2:$AC$281,"MAINTENANCE > *") -> 0 | J6: =COUNTIFS('Prácticas_Revisiones'!$S$2:$S$282,"T001",'Prácticas_Revisiones'!$T$2:$T$282,"SOFTWARE CONFIG. MGMT. > *")+COUNTIFS('Prácticas_Snowballing'!$AB$2:$AB$281,"T001",'Prácticas_Snowballing'!$AC$2:$AC$281,"SOFTWARE CONFIG. MGMT. > *") -> 0 | K6: =COUNTIFS('Prácticas_Revisiones'!$S$2:$S$282,"T001",'Prácticas_Revisiones'!$T$2:$T$282,"SOFTWARE ENG. PROCESS > *")+COUNTIFS('Prácticas_Snowballing'!$AB$2:$AB$281,"T001",'Prácticas_Snowballing'!$AC$2:$AC$281,"SOFTWARE ENG. PROCESS > *") -> 0 | L6: =COUNTIFS('Prácticas_Revisiones'!$S$2:$S$282,"T001",'Prácticas_Revisiones'!$T$2:$T$282,"SOFTWARE ENG. MODELS/METH. > *")+COUNTIFS('Prácticas_Snowballing'!$AB$2:$AB$281,"T001",'Prácticas_Snowballing'!$AC$2:$AC$281,"SOFTWARE ENG. MODELS/METH. > *") -> 0 | M6: =COUNTIFS('Prácticas_Revisiones'!$S$2:$S$282,"T001",'Prácticas_Revisiones'!$T$2:$T$282,"SOFTWARE QUALITY > *")+COUNTIFS('Prácticas_Snowballing'!$AB$2:$AB$281,"T001",'Prácticas_Snowballing'!$AC$2:$AC$281,"SOFTWARE QUALITY > *") -> 0 | N6: =COUNTIFS('Prácticas_Revisiones'!$S$2:$S$282,"T001",'Prácticas_Revisiones'!$T$2:$T$282,"SOFTWARE SECURITY > *")+COUNTIFS('Prácticas_Snowballing'!$AB$2:$AB$281,"T001",'Prácticas_Snowballing'!$AC$2:$AC$281,"SOFTWARE SECURITY > *") -> 0 | O6: =COUNTIFS('Prácticas_Revisiones'!$S$2:$S$282,"T001",'Prácticas_Revisiones'!$T$2:$T$282,"PROFESSIONAL PRACTICE > *")+COUNTIFS('Prácticas_Snowballing'!$AB$2:$AB$281,"T001",'Prácticas_Snowballing'!$AC$2:$AC$281,"PROFESSIONAL PRACTICE > *") -> 0 | P6: =COUNTIFS('Prácticas_Revisiones'!$S$2:$S$282,"T001",'Prácticas_Revisiones'!$T$2:$T$282,"SOFTWARE ENG. ECONOMICS > *")+COUNTIFS('Prácticas_Snowballing'!$AB$2:$AB$281,"T001",'Prácticas_Snowballing'!$AC$2:$AC$281,"SOFTWARE ENG. ECONOMICS > *") -> 0 | Q6: =COUNTIFS('Prácticas_Revisiones'!$S$2:$S$282,"T001",'Prácticas_Revisiones'!$T$2:$T$282,"SOFTWARE ENG. MANAGEMENT > *")+COUNTIFS('Prácticas_Snowballing'!$AB$2:$AB$281,"T001",'Prácticas_Snowballing'!$AC$2:$AC$281,"SOFTWARE ENG. MANAGEMENT > *") -> 0 | R6: =COUNTIFS('Prácticas_Revisiones'!$S$2:$S$282,"T001",'Prácticas_Revisiones'!$T$2:$T$282,"Sin área SWEBOK")+COUNTIFS('Prácticas_Snowballing'!$AB$2:$AB$281,"T001",'Prácticas_Snowballing'!$AC$2:$AC$281,"Sin área SWEBOK") -> 1 | S6: =SUM(C6:R6) -> 7
B7: T002 Exegética | C7: =COUNTIFS('Prácticas_Revisiones'!$S$2:$S$282,"T002",'Prácticas_Revisiones'!$T$2:$T$282,"REQUIREMENTS > *")+COUNTIFS('Prácticas_Snowballing'!$AB$2:$AB$281,"T002",'Prácticas_Snowballing'!$AC$2:$AC$281,"REQUIREMENTS > *") -> 0 | D7: =COUNTIFS('Prácticas_Revisiones'!$S$2:$S$282,"T002",'Prácticas_Revisiones'!$T$2:$T$282,"ARCHITECTURE > *")+COUNTIFS('Prácticas_Snowballing'!$AB$2:$AB$281,"T002",'Prácticas_Snowballing'!$AC$2:$AC$281,"ARCHITECTURE > *") -> 0 | E7: =COUNTIFS('Prácticas_Revisiones'!$S$2:$S$282,"T002",'Prácticas_Revisiones'!$T$2:$T$282,"DESIGN > *")+COUNTIFS('Prácticas_Snowballing'!$AB$2:$AB$281,"T002",'Prácticas_Snowballing'!$AC$2:$AC$281,"DESIGN > *") -> 0 | F7: =COUNTIFS('Prácticas_Revisiones'!$S$2:$S$282,"T002",'Prácticas_Revisiones'!$T$2:$T$282,"CONSTRUCTION > *")+COUNTIFS('Prácticas_Snowballing'!$AB$2:$AB$281,"T002",'Prácticas_Snowballing'!$AC$2:$AC$281,"CONSTRUCTION > *") -> 0 | G7: =COUNTIFS('Prácticas_Revisiones'!$S$2:$S$282,"T002",'Prácticas_Revisiones'!$T$2:$T$282,"SOFTWARE TESTING > *")+COUNTIFS('Prácticas_Snowballing'!$AB$2:$AB$281,"T002",'Prácticas_Snowballing'!$AC$2:$AC$281,"SOFTWARE TESTING > *") -> 0 | H7: =COUNTIFS('Prácticas_Revisiones'!$S$2:$S$282,"T002",'Prácticas_Revisiones'!$T$2:$T$282,"SOFTWARE ENG. OPERATIONS > *")+COUNTIFS('Prácticas_Snowballing'!$AB$2:$AB$281,"T002",'Prácticas_Snowballing'!$AC$2:$AC$281,"SOFTWARE ENG. OPERATIONS > *") -> 0 | I7: =COUNTIFS('Prácticas_Revisiones'!$S$2:$S$282,"T002",'Prácticas_Revisiones'!$T$2:$T$282,"MAINTENANCE > *")+COUNTIFS('Prácticas_Snowballing'!$AB$2:$AB$281,"T002",'Prácticas_Snowballing'!$AC$2:$AC$281,"MAINTENANCE > *") -> 0 | J7: =COUNTIFS('Prácticas_Revisiones'!$S$2:$S$282,"T002",'Prácticas_Revisiones'!$T$2:$T$282,"SOFTWARE CONFIG. MGMT. > *")+COUNTIFS('Prácticas_Snowballing'!$AB$2:$AB$281,"T002",'Prácticas_Snowballing'!$AC$2:$AC$281,"SOFTWARE CONFIG. MGMT. > *") -> 0 | K7: =COUNTIFS('Prácticas_Revisiones'!$S$2:$S$282,"T002",'Prácticas_Revisiones'!$T$2:$T$282,"SOFTWARE ENG. PROCESS > *")+COUNTIFS('Prácticas_Snowballing'!$AB$2:$AB$281,"T002",'Prácticas_Snowballing'!$AC$2:$AC$281,"SOFTWARE ENG. PROCESS > *") -> 0 | L7: =COUNTIFS('Prácticas_Revisiones'!$S$2:$S$282,"T002",'Prácticas_Revisiones'!$T$2:$T$282,"SOFTWARE ENG. MODELS/METH. > *")+COUNTIFS('Prácticas_Snowballing'!$AB$2:$AB$281,"T002",'Prácticas_Snowballing'!$AC$2:$AC$281,"SOFTWARE ENG. MODELS/METH. > *") -> 0 | M7: =COUNTIFS('Prácticas_Revisiones'!$S$2:$S$282,"T002",'Prácticas_Revisiones'!$T$2:$T$282,"SOFTWARE QUALITY > *")+COUNTIFS('Prácticas_Snowballing'!$AB$2:$AB$281,"T002",'Prácticas_Snowballing'!$AC$2:$AC$281,"SOFTWARE QUALITY > *") -> 0 | N7: =COUNTIFS('Prácticas_Revisiones'!$S$2:$S$282,"T002",'Prácticas_Revisiones'!$T$2:$T$282,"SOFTWARE SECURITY > *")+COUNTIFS('Prácticas_Snowballing'!$AB$2:$AB$281,"T002",'Prácticas_Snowballing'!$AC$2:$AC$281,"SOFTWARE SECURITY > *") -> 0 | O7: =COUNTIFS('Prácticas_Revisiones'!$S$2:$S$282,"T002",'Prácticas_Revisiones'!$T$2:$T$282,"PROFESSIONAL PRACTICE > *")+COUNTIFS('Prácticas_Snowballing'!$AB$2:$AB$281,"T002",'Prácticas_Snowballing'!$AC$2:$AC$281,"PROFESSIONAL PRACTICE > *") -> 0 | P7: =COUNTIFS('Prácticas_Revisiones'!$S$2:$S$282,"T002",'Prácticas_Revisiones'!$T$2:$T$282,"SOFTWARE ENG. ECONOMICS > *")+COUNTIFS('Prácticas_Snowballing'!$AB$2:$AB$281,"T002",'Prácticas_Snowballing'!$AC$2:$AC$281,"SOFTWARE ENG. ECONOMICS > *") -> 0 | Q7: =COUNTIFS('Prácticas_Revisiones'!$S$2:$S$282,"T002",'Prácticas_Revisiones'!$T$2:$T$282,"SOFTWARE ENG. MANAGEMENT > *")+COUNTIFS('Prácticas_Snowballing'!$AB$2:$AB$281,"T002",'Prácticas_Snowballing'!$AC$2:$AC$281,"SOFTWARE ENG. MANAGEMENT > *") -> 0 | R7: =COUNTIFS('Prácticas_Revisiones'!$S$2:$S$282,"T002",'Prácticas_Revisiones'!$T$2:$T$282,"Sin área SWEBOK")+COUNTIFS('Prácticas_Snowballing'!$AB$2:$AB$281,"T002",'Prácticas_Snowballing'!$AC$2:$AC$281,"Sin área SWEBOK") -> 0 | S7: =SUM(C7:R7) -> 0
B8: T003 Fábula | C8: =COUNTIFS('Prácticas_Revisiones'!$S$2:$S$282,"T003",'Prácticas_Revisiones'!$T$2:$T$282,"REQUIREMENTS > *")+COUNTIFS('Prácticas_Snowballing'!$AB$2:$AB$281,"T003",'Prácticas_Snowballing'!$AC$2:$AC$281,"REQUIREMENTS > *") -> 0 | D8: =COUNTIFS('Prácticas_Revisiones'!$S$2:$S$282,"T003",'Prácticas_Revisiones'!$T$2:$T$282,"ARCHITECTURE > *")+COUNTIFS('Prácticas_Snowballing'!$AB$2:$AB$281,"T003",'Prácticas_Snowballing'!$AC$2:$AC$281,"ARCHITECTURE > *") -> 0 | E8: =COUNTIFS('Prácticas_Revisiones'!$S$2:$S$282,"T003",'Prácticas_Revisiones'!$T$2:$T$282,"DESIGN > *")+COUNTIFS('Prácticas_Snowballing'!$AB$2:$AB$281,"T003",'Prácticas_Snowballing'!$AC$2:$AC$281,"DESIGN > *") -> 0 | F8: =COUNTIFS('Prácticas_Revisiones'!$S$2:$S$282,"T003",'Prácticas_Revisiones'!$T$2:$T$282,"CONSTRUCTION > *")+COUNTIFS('Prácticas_Snowballing'!$AB$2:$AB$281,"T003",'Prácticas_Snowballing'!$AC$2:$AC$281,"CONSTRUCTION > *") -> 0 | G8: =COUNTIFS('Prácticas_Revisiones'!$S$2:$S$282,"T003",'Prácticas_Revisiones'!$T$2:$T$282,"SOFTWARE TESTING > *")+COUNTIFS('Prácticas_Snowballing'!$AB$2:$AB$281,"T003",'Prácticas_Snowballing'!$AC$2:$AC$281,"SOFTWARE TESTING > *") -> 0 | H8: =COUNTIFS('Prácticas_Revisiones'!$S$2:$S$282,"T003",'Prácticas_Revisiones'!$T$2:$T$282,"SOFTWARE ENG. OPERATIONS > *")+COUNTIFS('Prácticas_Snowballing'!$AB$2:$AB$281,"T003",'Prácticas_Snowballing'!$AC$2:$AC$281,"SOFTWARE ENG. OPERATIONS > *") -> 0 | I8: =COUNTIFS('Prácticas_Revisiones'!$S$2:$S$282,"T003",'Prácticas_Revisiones'!$T$2:$T$282,"MAINTENANCE > *")+COUNTIFS('Prácticas_Snowballing'!$AB$2:$AB$281,"T003",'Prácticas_Snowballing'!$AC$2:$AC$281,"MAINTENANCE > *") -> 0 | J8: =COUNTIFS('Prácticas_Revisiones'!$S$2:$S$282,"T003",'Prácticas_Revisiones'!$T$2:$T$282,"SOFTWARE CONFIG. MGMT. > *")+COUNTIFS('Prácticas_Snowballing'!$AB$2:$AB$281,"T003",'Prácticas_Snowballing'!$AC$2:$AC$281,"SOFTWARE CONFIG. MGMT. > *") -> 0 | K8: =COUNTIFS('Prácticas_Revisiones'!$S$2:$S$282,"T003",'Prácticas_Revisiones'!$T$2:$T$282,"SOFTWARE ENG. PROCESS > *")+COUNTIFS('Prácticas_Snowballing'!$AB$2:$AB$281,"T003",'Prácticas_Snowballing'!$AC$2:$AC$281,"SOFTWARE ENG. PROCESS > *") -> 0 | L8: =COUNTIFS('Prácticas_Revisiones'!$S$2:$S$282,"T003",'Prácticas_Revisiones'!$T$2:$T$282,"SOFTWARE ENG. MODELS/METH. > *")+COUNTIFS('Prácticas_Snowballing'!$AB$2:$AB$281,"T003",'Prácticas_Snowballing'!$AC$2:$AC$281,"SOFTWARE ENG. MODELS/METH. > *") -> 0 | M8: =COUNTIFS('Prácticas_Revisiones'!$S$2:$S$282,"T003",'Prácticas_Revisiones'!$T$2:$T$282,"SOFTWARE QUALITY > *")+COUNTIFS('Prácticas_Snowballing'!$AB$2:$AB$281,"T003",'Prácticas_Snowballing'!$AC$2:$AC$281,"SOFTWARE QUALITY > *") -> 0 | N8: =COUNTIFS('Prácticas_Revisiones'!$S$2:$S$282,"T003",'Prácticas_Revisiones'!$T$2:$T$282,"SOFTWARE SECURITY > *")+COUNTIFS('Prácticas_Snowballing'!$AB$2:$AB$281,"T003",'Prácticas_Snowballing'!$AC$2:$AC$281,"SOFTWARE SECURITY > *") -> 0 | O8: =COUNTIFS('Prácticas_Revisiones'!$S$2:$S$282,"T003",'Prácticas_Revisiones'!$T$2:$T$282,"PROFESSIONAL PRACTICE > *")+COUNTIFS('Prácticas_Snowballing'!$AB$2:$AB$281,"T003",'Prácticas_Snowballing'!$AC$2:$AC$281,"PROFESSIONAL PRACTICE > *") -> 0 | P8: =COUNTIFS('Prácticas_Revisiones'!$S$2:$S$282,"T003",'Prácticas_Revisiones'!$T$2:$T$282,"SOFTWARE ENG. ECONOMICS > *")+COUNTIFS('Prácticas_Snowballing'!$AB$2:$AB$281,"T003",'Prácticas_Snowballing'!$AC$2:$AC$281,"SOFTWARE ENG. ECONOMICS > *") -> 0 | Q8: =COUNTIFS('Prácticas_Revisiones'!$S$2:$S$282,"T003",'Prácticas_Revisiones'!$T$2:$T$282,"SOFTWARE ENG. MANAGEMENT > *")+COUNTIFS('Prácticas_Snowballing'!$AB$2:$AB$281,"T003",'Prácticas_Snowballing'!$AC$2:$AC$281,"SOFTWARE ENG. MANAGEMENT > *") -> 0 | R8: =COUNTIFS('Prácticas_Revisiones'!$S$2:$S$282,"T003",'Prácticas_Revisiones'!$T$2:$T$282,"Sin área SWEBOK")+COUNTIFS('Prácticas_Snowballing'!$AB$2:$AB$281,"T003",'Prácticas_Snowballing'!$AC$2:$AC$281,"Sin área SWEBOK") -> 0 | S8: =SUM(C8:R8) -> 0
B9: T004 Mapa mental | C9: =COUNTIFS('Prácticas_Revisiones'!$S$2:$S$282,"T004",'Prácticas_Revisiones'!$T$2:$T$282,"REQUIREMENTS > *")+COUNTIFS('Prácticas_Snowballing'!$AB$2:$AB$281,"T004",'Prácticas_Snowballing'!$AC$2:$AC$281,"REQUIREMENTS > *") -> 0 | D9: =COUNTIFS('Prácticas_Revisiones'!$S$2:$S$282,"T004",'Prácticas_Revisiones'!$T$2:$T$282,"ARCHITECTURE > *")+COUNTIFS('Prácticas_Snowballing'!$AB$2:$AB$281,"T004",'Prácticas_Snowballing'!$AC$2:$AC$281,"ARCHITECTURE > *") -> 0 | E9: =COUNTIFS('Prácticas_Revisiones'!$S$2:$S$282,"T004",'Prácticas_Revisiones'!$T$2:$T$282,"DESIGN > *")+COUNTIFS('Prácticas_Snowballing'!$AB$2:$AB$281,"T004",'Prácticas_Snowballing'!$AC$2:$AC$281,"DESIGN > *") -> 0 | F9: =COUNTIFS('Prácticas_Revisiones'!$S$2:$S$282,"T004",'Prácticas_Revisiones'!$T$2:$T$282,"CONSTRUCTION > *")+COUNTIFS('Prácticas_Snowballing'!$AB$2:$AB$281,"T004",'Prácticas_Snowballing'!$AC$2:$AC$281,"CONSTRUCTION > *") -> 2 | G9: =COUNTIFS('Prácticas_Revisiones'!$S$2:$S$282,"T004",'Prácticas_Revisiones'!$T$2:$T$282,"SOFTWARE TESTING > *")+COUNTIFS('Prácticas_Snowballing'!$AB$2:$AB$281,"T004",'Prácticas_Snowballing'!$AC$2:$AC$281,"SOFTWARE TESTING > *") -> 0 | H9: =COUNTIFS('Prácticas_Revisiones'!$S$2:$S$282,"T004",'Prácticas_Revisiones'!$T$2:$T$282,"SOFTWARE ENG. OPERATIONS > *")+COUNTIFS('Prácticas_Snowballing'!$AB$2:$AB$281,"T004",'Prácticas_Snowballing'!$AC$2:$AC$281,"SOFTWARE ENG. OPERATIONS > *") -> 0 | I9: =COUNTIFS('Prácticas_Revisiones'!$S$2:$S$282,"T004",'Prácticas_Revisiones'!$T$2:$T$282,"MAINTENANCE > *")+COUNTIFS('Prácticas_Snowballing'!$AB$2:$AB$281,"T004",'Prácticas_Snowballing'!$AC$2:$AC$281,"MAINTENANCE > *") -> 0 | J9: =COUNTIFS('Prácticas_Revisiones'!$S$2:$S$282,"T004",'Prácticas_Revisiones'!$T$2:$T$282,"SOFTWARE CONFIG. MGMT. > *")+COUNTIFS('Prácticas_Snowballing'!$AB$2:$AB$281,"T004",'Prácticas_Snowballing'!$AC$2:$AC$281,"SOFTWARE CONFIG. MGMT. > *") -> 0 | K9: =COUNTIFS('Prácticas_Revisiones'!$S$2:$S$282,"T004",'Prácticas_Revisiones'!$T$2:$T$282,"SOFTWARE ENG. PROCESS > *")+COUNTIFS('Prácticas_Snowballing'!$AB$2:$AB$281,"T004",'Prácticas_Snowballing'!$AC$2:$AC$281,"SOFTWARE ENG. PROCESS > *") -> 0 | L9: =COUNTIFS('Prácticas_Revisiones'!$S$2:$S$282,"T004",'Prácticas_Revisiones'!$T$2:$T$282,"SOFTWARE ENG. MODELS/METH. > *")+COUNTIFS('Prácticas_Snowballing'!$AB$2:$AB$281,"T004",'Prácticas_Snowballing'!$AC$2:$AC$281,"SOFTWARE ENG. MODELS/METH. > *") -> 0 | M9: =COUNTIFS('Prácticas_Revisiones'!$S$2:$S$282,"T004",'Prácticas_Revisiones'!$T$2:$T$282,"SOFTWARE QUALITY > *")+COUNTIFS('Prácticas_Snowballing'!$AB$2:$AB$281,"T004",'Prácticas_Snowballing'!$AC$2:$AC$281,"SOFTWARE QUALITY > *") -> 0 | N9: =COUNTIFS('Prácticas_Revisiones'!$S$2:$S$282,"T004",'Prácticas_Revisiones'!$T$2:$T$282,"SOFTWARE SECURITY > *")+COUNTIFS('Prácticas_Snowballing'!$AB$2:$AB$281,"T004",'Prácticas_Snowballing'!$AC$2:$AC$281,"SOFTWARE SECURITY > *") -> 0 | O9: =COUNTIFS('Prácticas_Revisiones'!$S$2:$S$282,"T004",'Prácticas_Revisiones'!$T$2:$T$282,"PROFESSIONAL PRACTICE > *")+COUNTIFS('Prácticas_Snowballing'!$AB$2:$AB$281,"T004",'Prácticas_Snowballing'!$AC$2:$AC$281,"PROFESSIONAL PRACTICE > *") -> 0 | P9: =COUNTIFS('Prácticas_Revisiones'!$S$2:$S$282,"T004",'Prácticas_Revisiones'!$T$2:$T$282,"SOFTWARE ENG. ECONOMICS > *")+COUNTIFS('Prácticas_Snowballing'!$AB$2:$AB$281,"T004",'Prácticas_Snowballing'!$AC$2:$AC$281,"SOFTWARE ENG. ECONOMICS > *") -> 0 | Q9: =COUNTIFS('Prácticas_Revisiones'!$S$2:$S$282,"T004",'Prácticas_Revisiones'!$T$2:$T$282,"SOFTWARE ENG. MANAGEMENT > *")+COUNTIFS('Prácticas_Snowballing'!$AB$2:$AB$281,"T004",'Prácticas_Snowballing'!$AC$2:$AC$281,"SOFTWARE ENG. MANAGEMENT > *") -> 0 | R9: =COUNTIFS('Prácticas_Revisiones'!$S$2:$S$282,"T004",'Prácticas_Revisiones'!$T$2:$T$282,"Sin área SWEBOK")+COUNTIFS('Prácticas_Snowballing'!$AB$2:$AB$281,"T004",'Prácticas_Snowballing'!$AC$2:$AC$281,"Sin área SWEBOK") -> 0 | S9: =SUM(C9:R9) -> 2
B10: T005 Mnemotecnia | C10: =COUNTIFS('Prácticas_Revisiones'!$S$2:$S$282,"T005",'Prácticas_Revisiones'!$T$2:$T$282,"REQUIREMENTS > *")+COUNTIFS('Prácticas_Snowballing'!$AB$2:$AB$281,"T005",'Prácticas_Snowballing'!$AC$2:$AC$281,"REQUIREMENTS > *") -> 0 | D10: =COUNTIFS('Prácticas_Revisiones'!$S$2:$S$282,"T005",'Prácticas_Revisiones'!$T$2:$T$282,"ARCHITECTURE > *")+COUNTIFS('Prácticas_Snowballing'!$AB$2:$AB$281,"T005",'Prácticas_Snowballing'!$AC$2:$AC$281,"ARCHITECTURE > *") -> 0 | E10: =COUNTIFS('Prácticas_Revisiones'!$S$2:$S$282,"T005",'Prácticas_Revisiones'!$T$2:$T$282,"DESIGN > *")+COUNTIFS('Prácticas_Snowballing'!$AB$2:$AB$281,"T005",'Prácticas_Snowballing'!$AC$2:$AC$281,"DESIGN > *") -> 0 | F10: =COUNTIFS('Prácticas_Revisiones'!$S$2:$S$282,"T005",'Prácticas_Revisiones'!$T$2:$T$282,"CONSTRUCTION > *")+COUNTIFS('Prácticas_Snowballing'!$AB$2:$AB$281,"T005",'Prácticas_Snowballing'!$AC$2:$AC$281,"CONSTRUCTION > *") -> 0 | G10: =COUNTIFS('Prácticas_Revisiones'!$S$2:$S$282,"T005",'Prácticas_Revisiones'!$T$2:$T$282,"SOFTWARE TESTING > *")+COUNTIFS('Prácticas_Snowballing'!$AB$2:$AB$281,"T005",'Prácticas_Snowballing'!$AC$2:$AC$281,"SOFTWARE TESTING > *") -> 0 | H10: =COUNTIFS('Prácticas_Revisiones'!$S$2:$S$282,"T005",'Prácticas_Revisiones'!$T$2:$T$282,"SOFTWARE ENG. OPERATIONS > *")+COUNTIFS('Prácticas_Snowballing'!$AB$2:$AB$281,"T005",'Prácticas_Snowballing'!$AC$2:$AC$281,"SOFTWARE ENG. OPERATIONS > *") -> 0 | I10: =COUNTIFS('Prácticas_Revisiones'!$S$2:$S$282,"T005",'Prácticas_Revisiones'!$T$2:$T$282,"MAINTENANCE > *")+COUNTIFS('Prácticas_Snowballing'!$AB$2:$AB$281,"T005",'Prácticas_Snowballing'!$AC$2:$AC$281,"MAINTENANCE > *") -> 0 | J10: =COUNTIFS('Prácticas_Revisiones'!$S$2:$S$282,"T005",'Prácticas_Revisiones'!$T$2:$T$282,"SOFTWARE CONFIG. MGMT. > *")+COUNTIFS('Prácticas_Snowballing'!$AB$2:$AB$281,"T005",'Prácticas_Snowballing'!$AC$2:$AC$281,"SOFTWARE CONFIG. MGMT. > *") -> 0 | K10: =COUNTIFS('Prácticas_Revisiones'!$S$2:$S$282,"T005",'Prácticas_Revisiones'!$T$2:$T$282,"SOFTWARE ENG. PROCESS > *")+COUNTIFS('Prácticas_Snowballing'!$AB$2:$AB$281,"T005",'Prácticas_Snowballing'!$AC$2:$AC$281,"SOFTWARE ENG. PROCESS > *") -> 0 | L10: =COUNTIFS('Prácticas_Revisiones'!$S$2:$S$282,"T005",'Prácticas_Revisiones'!$T$2:$T$282,"SOFTWARE ENG. MODELS/METH. > *")+COUNTIFS('Prácticas_Snowballing'!$AB$2:$AB$281,"T005",'Prácticas_Snowballing'!$AC$2:$AC$281,"SOFTWARE ENG. MODELS/METH. > *") -> 0 | M10: =COUNTIFS('Prácticas_Revisiones'!$S$2:$S$282,"T005",'Prácticas_Revisiones'!$T$2:$T$282,"SOFTWARE QUALITY > *")+COUNTIFS('Prácticas_Snowballing'!$AB$2:$AB$281,"T005",'Prácticas_Snowballing'!$AC$2:$AC$281,"SOFTWARE QUALITY > *") -> 0 | N10: =COUNTIFS('Prácticas_Revisiones'!$S$2:$S$282,"T005",'Prácticas_Revisiones'!$T$2:$T$282,"SOFTWARE SECURITY > *")+COUNTIFS('Prácticas_Snowballing'!$AB$2:$AB$281,"T005",'Prácticas_Snowballing'!$AC$2:$AC$281,"SOFTWARE SECURITY > *") -> 0 | O10: =COUNTIFS('Prácticas_Revisiones'!$S$2:$S$282,"T005",'Prácticas_Revisiones'!$T$2:$T$282,"PROFESSIONAL PRACTICE > *")+COUNTIFS('Prácticas_Snowballing'!$AB$2:$AB$281,"T005",'Prácticas_Snowballing'!$AC$2:$AC$281,"PROFESSIONAL PRACTICE > *") -> 0 | P10: =COUNTIFS('Prácticas_Revisiones'!$S$2:$S$282,"T005",'Prácticas_Revisiones'!$T$2:$T$282,"SOFTWARE ENG. ECONOMICS > *")+COUNTIFS('Prácticas_Snowballing'!$AB$2:$AB$281,"T005",'Prácticas_Snowballing'!$AC$2:$AC$281,"SOFTWARE ENG. ECONOMICS > *") -> 0 | Q10: =COUNTIFS('Prácticas_Revisiones'!$S$2:$S$282,"T005",'Prácticas_Revisiones'!$T$2:$T$282,"SOFTWARE ENG. MANAGEMENT > *")+COUNTIFS('Prácticas_Snowballing'!$AB$2:$AB$281,"T005",'Prácticas_Snowballing'!$AC$2:$AC$281,"SOFTWARE ENG. MANAGEMENT > *") -> 0 | R10: =COUNTIFS('Prácticas_Revisiones'!$S$2:$S$282,"T005",'Prácticas_Revisiones'!$T$2:$T$282,"Sin área SWEBOK")+COUNTIFS('Prácticas_Snowballing'!$AB$2:$AB$281,"T005",'Prácticas_Snowballing'!$AC$2:$AC$281,"Sin área SWEBOK") -> 0 | S10: =SUM(C10:R10) -> 0
B11: T006 Pensamiento de diseño | C11: =COUNTIFS('Prácticas_Revisiones'!$S$2:$S$282,"T006",'Prácticas_Revisiones'!$T$2:$T$282,"REQUIREMENTS > *")+COUNTIFS('Prácticas_Snowballing'!$AB$2:$AB$281,"T006",'Prácticas_Snowballing'!$AC$2:$AC$281,"REQUIREMENTS > *") -> 0 | D11: =COUNTIFS('Prácticas_Revisiones'!$S$2:$S$282,"T006",'Prácticas_Revisiones'!$T$2:$T$282,"ARCHITECTURE > *")+COUNTIFS('Prácticas_Snowballing'!$AB$2:$AB$281,"T006",'Prácticas_Snowballing'!$AC$2:$AC$281,"ARCHITECTURE > *") -> 0 | E11: =COUNTIFS('Prácticas_Revisiones'!$S$2:$S$282,"T006",'Prácticas_Revisiones'!$T$2:$T$282,"DESIGN > *")+COUNTIFS('Prácticas_Snowballing'!$AB$2:$AB$281,"T006",'Prácticas_Snowballing'!$AC$2:$AC$281,"DESIGN > *") -> 1 | F11: =COUNTIFS('Prácticas_Revisiones'!$S$2:$S$282,"T006",'Prácticas_Revisiones'!$T$2:$T$282,"CONSTRUCTION > *")+COUNTIFS('Prácticas_Snowballing'!$AB$2:$AB$281,"T006",'Prácticas_Snowballing'!$AC$2:$AC$281,"CONSTRUCTION > *") -> 0 | G11: =COUNTIFS('Prácticas_Revisiones'!$S$2:$S$282,"T006",'Prácticas_Revisiones'!$T$2:$T$282,"SOFTWARE TESTING > *")+COUNTIFS('Prácticas_Snowballing'!$AB$2:$AB$281,"T006",'Prácticas_Snowballing'!$AC$2:$AC$281,"SOFTWARE TESTING > *") -> 0 | H11: =COUNTIFS('Prácticas_Revisiones'!$S$2:$S$282,"T006",'Prácticas_Revisiones'!$T$2:$T$282,"SOFTWARE ENG. OPERATIONS > *")+COUNTIFS('Prácticas_Snowballing'!$AB$2:$AB$281,"T006",'Prácticas_Snowballing'!$AC$2:$AC$281,"SOFTWARE ENG. OPERATIONS > *") -> 0 | I11: =COUNTIFS('Prácticas_Revisiones'!$S$2:$S$282,"T006",'Prácticas_Revisiones'!$T$2:$T$282,"MAINTENANCE > *")+COUNTIFS('Prácticas_Snowballing'!$AB$2:$AB$281,"T006",'Prácticas_Snowballing'!$AC$2:$AC$281,"MAINTENANCE > *") -> 0 | J11: =COUNTIFS('Prácticas_Revisiones'!$S$2:$S$282,"T006",'Prácticas_Revisiones'!$T$2:$T$282,"SOFTWARE CONFIG. MGMT. > *")+COUNTIFS('Prácticas_Snowballing'!$AB$2:$AB$281,"T006",'Prácticas_Snowballing'!$AC$2:$AC$281,"SOFTWARE CONFIG. MGMT. > *") -> 0 | K11: =COUNTIFS('Prácticas_Revisiones'!$S$2:$S$282,"T006",'Prácticas_Revisiones'!$T$2:$T$282,"SOFTWARE ENG. PROCESS > *")+COUNTIFS('Prácticas_Snowballing'!$AB$2:$AB$281,"T006",'Prácticas_Snowballing'!$AC$2:$AC$281,"SOFTWARE ENG. PROCESS > *") -> 0 | L11: =COUNTIFS('Prácticas_Revisiones'!$S$2:$S$282,"T006",'Prácticas_Revisiones'!$T$2:$T$282,"SOFTWARE ENG. MODELS/METH. > *")+COUNTIFS('Prácticas_Snowballing'!$AB$2:$AB$281,"T006",'Prácticas_Snowballing'!$AC$2:$AC$281,"SOFTWARE ENG. MODELS/METH. > *") -> 0 | M11: =COUNTIFS('Prácticas_Revisiones'!$S$2:$S$282,"T006",'Prácticas_Revisiones'!$T$2:$T$282,"SOFTWARE QUALITY > *")+COUNTIFS('Prácticas_Snowballing'!$AB$2:$AB$281,"T006",'Prácticas_Snowballing'!$AC$2:$AC$281,"SOFTWARE QUALITY > *") -> 0 | N11: =COUNTIFS('Prácticas_Revisiones'!$S$2:$S$282,"T006",'Prácticas_Revisiones'!$T$2:$T$282,"SOFTWARE SECURITY > *")+COUNTIFS('Prácticas_Snowballing'!$AB$2:$AB$281,"T006",'Prácticas_Snowballing'!$AC$2:$AC$281,"SOFTWARE SECURITY > *") -> 0 | O11: =COUNTIFS('Prácticas_Revisiones'!$S$2:$S$282,"T006",'Prácticas_Revisiones'!$T$2:$T$282,"PROFESSIONAL PRACTICE > *")+COUNTIFS('Prácticas_Snowballing'!$AB$2:$AB$281,"T006",'Prácticas_Snowballing'!$AC$2:$AC$281,"PROFESSIONAL PRACTICE > *") -> 0 | P11: =COUNTIFS('Prácticas_Revisiones'!$S$2:$S$282,"T006",'Prácticas_Revisiones'!$T$2:$T$282,"SOFTWARE ENG. ECONOMICS > *")+COUNTIFS('Prácticas_Snowballing'!$AB$2:$AB$281,"T006",'Prácticas_Snowballing'!$AC$2:$AC$281,"SOFTWARE ENG. ECONOMICS > *") -> 0 | Q11: =COUNTIFS('Prácticas_Revisiones'!$S$2:$S$282,"T006",'Prácticas_Revisiones'!$T$2:$T$282,"SOFTWARE ENG. MANAGEMENT > *")+COUNTIFS('Prácticas_Snowballing'!$AB$2:$AB$281,"T006",'Prácticas_Snowballing'!$AC$2:$AC$281,"SOFTWARE ENG. MANAGEMENT > *") -> 0 | R11: =COUNTIFS('Prácticas_Revisiones'!$S$2:$S$282,"T006",'Prácticas_Revisiones'!$T$2:$T$282,"Sin área SWEBOK")+COUNTIFS('Prácticas_Snowballing'!$AB$2:$AB$281,"T006",'Prácticas_Snowballing'!$AC$2:$AC$281,"Sin área SWEBOK") -> 0 | S11: =SUM(C11:R11) -> 1
B12: T007 Preguntas y premios | C12: =COUNTIFS('Prácticas_Revisiones'!$S$2:$S$282,"T007",'Prácticas_Revisiones'!$T$2:$T$282,"REQUIREMENTS > *")+COUNTIFS('Prácticas_Snowballing'!$AB$2:$AB$281,"T007",'Prácticas_Snowballing'!$AC$2:$AC$281,"REQUIREMENTS > *") -> 0 | D12: =COUNTIFS('Prácticas_Revisiones'!$S$2:$S$282,"T007",'Prácticas_Revisiones'!$T$2:$T$282,"ARCHITECTURE > *")+COUNTIFS('Prácticas_Snowballing'!$AB$2:$AB$281,"T007",'Prácticas_Snowballing'!$AC$2:$AC$281,"ARCHITECTURE > *") -> 0 | E12: =COUNTIFS('Prácticas_Revisiones'!$S$2:$S$282,"T007",'Prácticas_Revisiones'!$T$2:$T$282,"DESIGN > *")+COUNTIFS('Prácticas_Snowballing'!$AB$2:$AB$281,"T007",'Prácticas_Snowballing'!$AC$2:$AC$281,"DESIGN > *") -> 0 | F12: =COUNTIFS('Prácticas_Revisiones'!$S$2:$S$282,"T007",'Prácticas_Revisiones'!$T$2:$T$282,"CONSTRUCTION > *")+COUNTIFS('Prácticas_Snowballing'!$AB$2:$AB$281,"T007",'Prácticas_Snowballing'!$AC$2:$AC$281,"CONSTRUCTION > *") -> 1 | G12: =COUNTIFS('Prácticas_Revisiones'!$S$2:$S$282,"T007",'Prácticas_Revisiones'!$T$2:$T$282,"SOFTWARE TESTING > *")+COUNTIFS('Prácticas_Snowballing'!$AB$2:$AB$281,"T007",'Prácticas_Snowballing'!$AC$2:$AC$281,"SOFTWARE TESTING > *") -> 0 | H12: =COUNTIFS('Prácticas_Revisiones'!$S$2:$S$282,"T007",'Prácticas_Revisiones'!$T$2:$T$282,"SOFTWARE ENG. OPERATIONS > *")+COUNTIFS('Prácticas_Snowballing'!$AB$2:$AB$281,"T007",'Prácticas_Snowballing'!$AC$2:$AC$281,"SOFTWARE ENG. OPERATIONS > *") -> 0 | I12: =COUNTIFS('Prácticas_Revisiones'!$S$2:$S$282,"T007",'Prácticas_Revisiones'!$T$2:$T$282,"MAINTENANCE > *")+COUNTIFS('Prácticas_Snowballing'!$AB$2:$AB$281,"T007",'Prácticas_Snowballing'!$AC$2:$AC$281,"MAINTENANCE > *") -> 0 | J12: =COUNTIFS('Prácticas_Revisiones'!$S$2:$S$282,"T007",'Prácticas_Revisiones'!$T$2:$T$282,"SOFTWARE CONFIG. MGMT. > *")+COUNTIFS('Prácticas_Snowballing'!$AB$2:$AB$281,"T007",'Prácticas_Snowballing'!$AC$2:$AC$281,"SOFTWARE CONFIG. MGMT. > *") -> 0 | K12: =COUNTIFS('Prácticas_Revisiones'!$S$2:$S$282,"T007",'Prácticas_Revisiones'!$T$2:$T$282,"SOFTWARE ENG. PROCESS > *")+COUNTIFS('Prácticas_Snowballing'!$AB$2:$AB$281,"T007",'Prácticas_Snowballing'!$AC$2:$AC$281,"SOFTWARE ENG. PROCESS > *") -> 0 | L12: =COUNTIFS('Prácticas_Revisiones'!$S$2:$S$282,"T007",'Prácticas_Revisiones'!$T$2:$T$282,"SOFTWARE ENG. MODELS/METH. > *")+COUNTIFS('Prácticas_Snowballing'!$AB$2:$AB$281,"T007",'Prácticas_Snowballing'!$AC$2:$AC$281,"SOFTWARE ENG. MODELS/METH. > *") -> 0 | M12: =COUNTIFS('Prácticas_Revisiones'!$S$2:$S$282,"T007",'Prácticas_Revisiones'!$T$2:$T$282,"SOFTWARE QUALITY > *")+COUNTIFS('Prácticas_Snowballing'!$AB$2:$AB$281,"T007",'Prácticas_Snowballing'!$AC$2:$AC$281,"SOFTWARE QUALITY > *") -> 0 | N12: =COUNTIFS('Prácticas_Revisiones'!$S$2:$S$282,"T007",'Prácticas_Revisiones'!$T$2:$T$282,"SOFTWARE SECURITY > *")+COUNTIFS('Prácticas_Snowballing'!$AB$2:$AB$281,"T007",'Prácticas_Snowballing'!$AC$2:$AC$281,"SOFTWARE SECURITY > *") -> 0 | O12: =COUNTIFS('Prácticas_Revisiones'!$S$2:$S$282,"T007",'Prácticas_Revisiones'!$T$2:$T$282,"PROFESSIONAL PRACTICE > *")+COUNTIFS('Prácticas_Snowballing'!$AB$2:$AB$281,"T007",'Prácticas_Snowballing'!$AC$2:$AC$281,"PROFESSIONAL PRACTICE > *") -> 0 | P12: =COUNTIFS('Prácticas_Revisiones'!$S$2:$S$282,"T007",'Prácticas_Revisiones'!$T$2:$T$282,"SOFTWARE ENG. ECONOMICS > *")+COUNTIFS('Prácticas_Snowballing'!$AB$2:$AB$281,"T007",'Prácticas_Snowballing'!$AC$2:$AC$281,"SOFTWARE ENG. ECONOMICS > *") -> 0 | Q12: =COUNTIFS('Prácticas_Revisiones'!$S$2:$S$282,"T007",'Prácticas_Revisiones'!$T$2:$T$282,"SOFTWARE ENG. MANAGEMENT > *")+COUNTIFS('Prácticas_Snowballing'!$AB$2:$AB$281,"T007",'Prácticas_Snowballing'!$AC$2:$AC$281,"SOFTWARE ENG. MANAGEMENT > *") -> 0 | R12: =COUNTIFS('Prácticas_Revisiones'!$S$2:$S$282,"T007",'Prácticas_Revisiones'!$T$2:$T$282,"Sin área SWEBOK")+COUNTIFS('Prácticas_Snowballing'!$AB$2:$AB$281,"T007",'Prácticas_Snowballing'!$AC$2:$AC$281,"Sin área SWEBOK") -> 0 | S12: =SUM(C12:R12) -> 1
B13: T008 Resumen | C13: =COUNTIFS('Prácticas_Revisiones'!$S$2:$S$282,"T008",'Prácticas_Revisiones'!$T$2:$T$282,"REQUIREMENTS > *")+COUNTIFS('Prácticas_Snowballing'!$AB$2:$AB$281,"T008",'Prácticas_Snowballing'!$AC$2:$AC$281,"REQUIREMENTS > *") -> 0 | D13: =COUNTIFS('Prácticas_Revisiones'!$S$2:$S$282,"T008",'Prácticas_Revisiones'!$T$2:$T$282,"ARCHITECTURE > *")+COUNTIFS('Prácticas_Snowballing'!$AB$2:$AB$281,"T008",'Prácticas_Snowballing'!$AC$2:$AC$281,"ARCHITECTURE > *") -> 0 | E13: =COUNTIFS('Prácticas_Revisiones'!$S$2:$S$282,"T008",'Prácticas_Revisiones'!$T$2:$T$282,"DESIGN > *")+COUNTIFS('Prácticas_Snowballing'!$AB$2:$AB$281,"T008",'Prácticas_Snowballing'!$AC$2:$AC$281,"DESIGN > *") -> 0 | F13: =COUNTIFS('Prácticas_Revisiones'!$S$2:$S$282,"T008",'Prácticas_Revisiones'!$T$2:$T$282,"CONSTRUCTION > *")+COUNTIFS('Prácticas_Snowballing'!$AB$2:$AB$281,"T008",'Prácticas_Snowballing'!$AC$2:$AC$281,"CONSTRUCTION > *") -> 1 | G13: =COUNTIFS('Prácticas_Revisiones'!$S$2:$S$282,"T008",'Prácticas_Revisiones'!$T$2:$T$282,"SOFTWARE TESTING > *")+COUNTIFS('Prácticas_Snowballing'!$AB$2:$AB$281,"T008",'Prácticas_Snowballing'!$AC$2:$AC$281,"SOFTWARE TESTING > *") -> 0 | H13: =COUNTIFS('Prácticas_Revisiones'!$S$2:$S$282,"T008",'Prácticas_Revisiones'!$T$2:$T$282,"SOFTWARE ENG. OPERATIONS > *")+COUNTIFS('Prácticas_Snowballing'!$AB$2:$AB$281,"T008",'Prácticas_Snowballing'!$AC$2:$AC$281,"SOFTWARE ENG. OPERATIONS > *") -> 0 | I13: =COUNTIFS('Prácticas_Revisiones'!$S$2:$S$282,"T008",'Prácticas_Revisiones'!$T$2:$T$282,"MAINTENANCE > *")+COUNTIFS('Prácticas_Snowballing'!$AB$2:$AB$281,"T008",'Prácticas_Snowballing'!$AC$2:$AC$281,"MAINTENANCE > *") -> 0 | J13: =COUNTIFS('Prácticas_Revisiones'!$S$2:$S$282,"T008",'Prácticas_Revisiones'!$T$2:$T$282,"SOFTWARE CONFIG. MGMT. > *")+COUNTIFS('Prácticas_Snowballing'!$AB$2:$AB$281,"T008",'Prácticas_Snowballing'!$AC$2:$AC$281,"SOFTWARE CONFIG. MGMT. > *") -> 0 | K13: =COUNTIFS('Prácticas_Revisiones'!$S$2:$S$282,"T008",'Prácticas_Revisiones'!$T$2:$T$282,"SOFTWARE ENG. PROCESS > *")+COUNTIFS('Prácticas_Snowballing'!$AB$2:$AB$281,"T008",'Prácticas_Snowballing'!$AC$2:$AC$281,"SOFTWARE ENG. PROCESS > *") -> 0 | L13: =COUNTIFS('Prácticas_Revisiones'!$S$2:$S$282,"T008",'Prácticas_Revisiones'!$T$2:$T$282,"SOFTWARE ENG. MODELS/METH. > *")+COUNTIFS('Prácticas_Snowballing'!$AB$2:$AB$281,"T008",'Prácticas_Snowballing'!$AC$2:$AC$281,"SOFTWARE ENG. MODELS/METH. > *") -> 0 | M13: =COUNTIFS('Prácticas_Revisiones'!$S$2:$S$282,"T008",'Prácticas_Revisiones'!$T$2:$T$282,"SOFTWARE QUALITY > *")+COUNTIFS('Prácticas_Snowballing'!$AB$2:$AB$281,"T008",'Prácticas_Snowballing'!$AC$2:$AC$281,"SOFTWARE QUALITY > *") -> 0 | N13: =COUNTIFS('Prácticas_Revisiones'!$S$2:$S$282,"T008",'Prácticas_Revisiones'!$T$2:$T$282,"SOFTWARE SECURITY > *")+COUNTIFS('Prácticas_Snowballing'!$AB$2:$AB$281,"T008",'Prácticas_Snowballing'!$AC$2:$AC$281,"SOFTWARE SECURITY > *") -> 0 | O13: =COUNTIFS('Prácticas_Revisiones'!$S$2:$S$282,"T008",'Prácticas_Revisiones'!$T$2:$T$282,"PROFESSIONAL PRACTICE > *")+COUNTIFS('Prácticas_Snowballing'!$AB$2:$AB$281,"T008",'Prácticas_Snowballing'!$AC$2:$AC$281,"PROFESSIONAL PRACTICE > *") -> 0 | P13: =COUNTIFS('Prácticas_Revisiones'!$S$2:$S$282,"T008",'Prácticas_Revisiones'!$T$2:$T$282,"SOFTWARE ENG. ECONOMICS > *")+COUNTIFS('Prácticas_Snowballing'!$AB$2:$AB$281,"T008",'Prácticas_Snowballing'!$AC$2:$AC$281,"SOFTWARE ENG. ECONOMICS > *") -> 0 | Q13: =COUNTIFS('Prácticas_Revisiones'!$S$2:$S$282,"T008",'Prácticas_Revisiones'!$T$2:$T$282,"SOFTWARE ENG. MANAGEMENT > *")+COUNTIFS('Prácticas_Snowballing'!$AB$2:$AB$281,"T008",'Prácticas_Snowballing'!$AC$2:$AC$281,"SOFTWARE ENG. MANAGEMENT > *") -> 0 | R13: =COUNTIFS('Prácticas_Revisiones'!$S$2:$S$282,"T008",'Prácticas_Revisiones'!$T$2:$T$282,"Sin área SWEBOK")+COUNTIFS('Prácticas_Snowballing'!$AB$2:$AB$281,"T008",'Prácticas_Snowballing'!$AC$2:$AC$281,"Sin área SWEBOK") -> 1 | S13: =SUM(C13:R13) -> 2
B14: T009 SCAMPER | C14: =COUNTIFS('Prácticas_Revisiones'!$S$2:$S$282,"T009",'Prácticas_Revisiones'!$T$2:$T$282,"REQUIREMENTS > *")+COUNTIFS('Prácticas_Snowballing'!$AB$2:$AB$281,"T009",'Prácticas_Snowballing'!$AC$2:$AC$281,"REQUIREMENTS > *") -> 0 | D14: =COUNTIFS('Prácticas_Revisiones'!$S$2:$S$282,"T009",'Prácticas_Revisiones'!$T$2:$T$282,"ARCHITECTURE > *")+COUNTIFS('Prácticas_Snowballing'!$AB$2:$AB$281,"T009",'Prácticas_Snowballing'!$AC$2:$AC$281,"ARCHITECTURE > *") -> 0 | E14: =COUNTIFS('Prácticas_Revisiones'!$S$2:$S$282,"T009",'Prácticas_Revisiones'!$T$2:$T$282,"DESIGN > *")+COUNTIFS('Prácticas_Snowballing'!$AB$2:$AB$281,"T009",'Prácticas_Snowballing'!$AC$2:$AC$281,"DESIGN > *") -> 0 | F14: =COUNTIFS('Prácticas_Revisiones'!$S$2:$S$282,"T009",'Prácticas_Revisiones'!$T$2:$T$282,"CONSTRUCTION > *")+COUNTIFS('Prácticas_Snowballing'!$AB$2:$AB$281,"T009",'Prácticas_Snowballing'!$AC$2:$AC$281,"CONSTRUCTION > *") -> 1 | G14: =COUNTIFS('Prácticas_Revisiones'!$S$2:$S$282,"T009",'Prácticas_Revisiones'!$T$2:$T$282,"SOFTWARE TESTING > *")+COUNTIFS('Prácticas_Snowballing'!$AB$2:$AB$281,"T009",'Prácticas_Snowballing'!$AC$2:$AC$281,"SOFTWARE TESTING > *") -> 0 | H14: =COUNTIFS('Prácticas_Revisiones'!$S$2:$S$282,"T009",'Prácticas_Revisiones'!$T$2:$T$282,"SOFTWARE ENG. OPERATIONS > *")+COUNTIFS('Prácticas_Snowballing'!$AB$2:$AB$281,"T009",'Prácticas_Snowballing'!$AC$2:$AC$281,"SOFTWARE ENG. OPERATIONS > *") -> 0 | I14: =COUNTIFS('Prácticas_Revisiones'!$S$2:$S$282,"T009",'Prácticas_Revisiones'!$T$2:$T$282,"MAINTENANCE > *")+COUNTIFS('Prácticas_Snowballing'!$AB$2:$AB$281,"T009",'Prácticas_Snowballing'!$AC$2:$AC$281,"MAINTENANCE > *") -> 0 | J14: =COUNTIFS('Prácticas_Revisiones'!$S$2:$S$282,"T009",'Prácticas_Revisiones'!$T$2:$T$282,"SOFTWARE CONFIG. MGMT. > *")+COUNTIFS('Prácticas_Snowballing'!$AB$2:$AB$281,"T009",'Prácticas_Snowballing'!$AC$2:$AC$281,"SOFTWARE CONFIG. MGMT. > *") -> 0 | K14: =COUNTIFS('Prácticas_Revisiones'!$S$2:$S$282,"T009",'Prácticas_Revisiones'!$T$2:$T$282,"SOFTWARE ENG. PROCESS > *")+COUNTIFS('Prácticas_Snowballing'!$AB$2:$AB$281,"T009",'Prácticas_Snowballing'!$AC$2:$AC$281,"SOFTWARE ENG. PROCESS > *") -> 0 | L14: =COUNTIFS('Prácticas_Revisiones'!$S$2:$S$282,"T009",'Prácticas_Revisiones'!$T$2:$T$282,"SOFTWARE ENG. MODELS/METH. > *")+COUNTIFS('Prácticas_Snowballing'!$AB$2:$AB$281,"T009",'Prácticas_Snowballing'!$AC$2:$AC$281,"SOFTWARE ENG. MODELS/METH. > *") -> 0 | M14: =COUNTIFS('Prácticas_Revisiones'!$S$2:$S$282,"T009",'Prácticas_Revisiones'!$T$2:$T$282,"SOFTWARE QUALITY > *")+COUNTIFS('Prácticas_Snowballing'!$AB$2:$AB$281,"T009",'Prácticas_Snowballing'!$AC$2:$AC$281,"SOFTWARE QUALITY > *") -> 0 | N14: =COUNTIFS('Prácticas_Revisiones'!$S$2:$S$282,"T009",'Prácticas_Revisiones'!$T$2:$T$282,"SOFTWARE SECURITY > *")+COUNTIFS('Prácticas_Snowballing'!$AB$2:$AB$281,"T009",'Prácticas_Snowballing'!$AC$2:$AC$281,"SOFTWARE SECURITY > *") -> 0 | O14: =COUNTIFS('Prácticas_Revisiones'!$S$2:$S$282,"T009",'Prácticas_Revisiones'!$T$2:$T$282,"PROFESSIONAL PRACTICE > *")+COUNTIFS('Prácticas_Snowballing'!$AB$2:$AB$281,"T009",'Prácticas_Snowballing'!$AC$2:$AC$281,"PROFESSIONAL PRACTICE > *") -> 0 | P14: =COUNTIFS('Prácticas_Revisiones'!$S$2:$S$282,"T009",'Prácticas_Revisiones'!$T$2:$T$282,"SOFTWARE ENG. ECONOMICS > *")+COUNTIFS('Prácticas_Snowballing'!$AB$2:$AB$281,"T009",'Prácticas_Snowballing'!$AC$2:$AC$281,"SOFTWARE ENG. ECONOMICS > *") -> 0 | Q14: =COUNTIFS('Prácticas_Revisiones'!$S$2:$S$282,"T009",'Prácticas_Revisiones'!$T$2:$T$282,"SOFTWARE ENG. MANAGEMENT > *")+COUNTIFS('Prácticas_Snowballing'!$AB$2:$AB$281,"T009",'Prácticas_Snowballing'!$AC$2:$AC$281,"SOFTWARE ENG. MANAGEMENT > *") -> 0 | R14: =COUNTIFS('Prácticas_Revisiones'!$S$2:$S$282,"T009",'Prácticas_Revisiones'!$T$2:$T$282,"Sin área SWEBOK")+COUNTIFS('Prácticas_Snowballing'!$AB$2:$AB$281,"T009",'Prácticas_Snowballing'!$AC$2:$AC$281,"Sin área SWEBOK") -> 0 | S14: =SUM(C14:R14) -> 1
B15: T010 SQA | C15: =COUNTIFS('Prácticas_Revisiones'!$S$2:$S$282,"T010",'Prácticas_Revisiones'!$T$2:$T$282,"REQUIREMENTS > *")+COUNTIFS('Prácticas_Snowballing'!$AB$2:$AB$281,"T010",'Prácticas_Snowballing'!$AC$2:$AC$281,"REQUIREMENTS > *") -> 0 | D15: =COUNTIFS('Prácticas_Revisiones'!$S$2:$S$282,"T010",'Prácticas_Revisiones'!$T$2:$T$282,"ARCHITECTURE > *")+COUNTIFS('Prácticas_Snowballing'!$AB$2:$AB$281,"T010",'Prácticas_Snowballing'!$AC$2:$AC$281,"ARCHITECTURE > *") -> 0 | E15: =COUNTIFS('Prácticas_Revisiones'!$S$2:$S$282,"T010",'Prácticas_Revisiones'!$T$2:$T$282,"DESIGN > *")+COUNTIFS('Prácticas_Snowballing'!$AB$2:$AB$281,"T010",'Prácticas_Snowballing'!$AC$2:$AC$281,"DESIGN > *") -> 0 | F15: =COUNTIFS('Prácticas_Revisiones'!$S$2:$S$282,"T010",'Prácticas_Revisiones'!$T$2:$T$282,"CONSTRUCTION > *")+COUNTIFS('Prácticas_Snowballing'!$AB$2:$AB$281,"T010",'Prácticas_Snowballing'!$AC$2:$AC$281,"CONSTRUCTION > *") -> 0 | G15: =COUNTIFS('Prácticas_Revisiones'!$S$2:$S$282,"T010",'Prácticas_Revisiones'!$T$2:$T$282,"SOFTWARE TESTING > *")+COUNTIFS('Prácticas_Snowballing'!$AB$2:$AB$281,"T010",'Prácticas_Snowballing'!$AC$2:$AC$281,"SOFTWARE TESTING > *") -> 0 | H15: =COUNTIFS('Prácticas_Revisiones'!$S$2:$S$282,"T010",'Prácticas_Revisiones'!$T$2:$T$282,"SOFTWARE ENG. OPERATIONS > *")+COUNTIFS('Prácticas_Snowballing'!$AB$2:$AB$281,"T010",'Prácticas_Snowballing'!$AC$2:$AC$281,"SOFTWARE ENG. OPERATIONS > *") -> 0 | I15: =COUNTIFS('Prácticas_Revisiones'!$S$2:$S$282,"T010",'Prácticas_Revisiones'!$T$2:$T$282,"MAINTENANCE > *")+COUNTIFS('Prácticas_Snowballing'!$AB$2:$AB$281,"T010",'Prácticas_Snowballing'!$AC$2:$AC$281,"MAINTENANCE > *") -> 0 | J15: =COUNTIFS('Prácticas_Revisiones'!$S$2:$S$282,"T010",'Prácticas_Revisiones'!$T$2:$T$282,"SOFTWARE CONFIG. MGMT. > *")+COUNTIFS('Prácticas_Snowballing'!$AB$2:$AB$281,"T010",'Prácticas_Snowballing'!$AC$2:$AC$281,"SOFTWARE CONFIG. MGMT. > *") -> 0 | K15: =COUNTIFS('Prácticas_Revisiones'!$S$2:$S$282,"T010",'Prácticas_Revisiones'!$T$2:$T$282,"SOFTWARE ENG. PROCESS > *")+COUNTIFS('Prácticas_Snowballing'!$AB$2:$AB$281,"T010",'Prácticas_Snowballing'!$AC$2:$AC$281,"SOFTWARE ENG. PROCESS > *") -> 0 | L15: =COUNTIFS('Prácticas_Revisiones'!$S$2:$S$282,"T010",'Prácticas_Revisiones'!$T$2:$T$282,"SOFTWARE ENG. MODELS/METH. > *")+COUNTIFS('Prácticas_Snowballing'!$AB$2:$AB$281,"T010",'Prácticas_Snowballing'!$AC$2:$AC$281,"SOFTWARE ENG. MODELS/METH. > *") -> 0 | M15: =COUNTIFS('Prácticas_Revisiones'!$S$2:$S$282,"T010",'Prácticas_Revisiones'!$T$2:$T$282,"SOFTWARE QUALITY > *")+COUNTIFS('Prácticas_Snowballing'!$AB$2:$AB$281,"T010",'Prácticas_Snowballing'!$AC$2:$AC$281,"SOFTWARE QUALITY > *") -> 0 | N15: =COUNTIFS('Prácticas_Revisiones'!$S$2:$S$282,"T010",'Prácticas_Revisiones'!$T$2:$T$282,"SOFTWARE SECURITY > *")+COUNTIFS('Prácticas_Snowballing'!$AB$2:$AB$281,"T010",'Prácticas_Snowballing'!$AC$2:$AC$281,"SOFTWARE SECURITY > *") -> 0 | O15: =COUNTIFS('Prácticas_Revisiones'!$S$2:$S$282,"T010",'Prácticas_Revisiones'!$T$2:$T$282,"PROFESSIONAL PRACTICE > *")+COUNTIFS('Prácticas_Snowballing'!$AB$2:$AB$281,"T010",'Prácticas_Snowballing'!$AC$2:$AC$281,"PROFESSIONAL PRACTICE > *") -> 0 | P15: =COUNTIFS('Prácticas_Revisiones'!$S$2:$S$282,"T010",'Prácticas_Revisiones'!$T$2:$T$282,"SOFTWARE ENG. ECONOMICS > *")+COUNTIFS('Prácticas_Snowballing'!$AB$2:$AB$281,"T010",'Prácticas_Snowballing'!$AC$2:$AC$281,"SOFTWARE ENG. ECONOMICS > *") -> 0 | Q15: =COUNTIFS('Prácticas_Revisiones'!$S$2:$S$282,"T010",'Prácticas_Revisiones'!$T$2:$T$282,"SOFTWARE ENG. MANAGEMENT > *")+COUNTIFS('Prácticas_Snowballing'!$AB$2:$AB$281,"T010",'Prácticas_Snowballing'!$AC$2:$AC$281,"SOFTWARE ENG. MANAGEMENT > *") -> 0 | R15: =COUNTIFS('Prácticas_Revisiones'!$S$2:$S$282,"T010",'Prácticas_Revisiones'!$T$2:$T$282,"Sin área SWEBOK")+COUNTIFS('Prácticas_Snowballing'!$AB$2:$AB$281,"T010",'Prácticas_Snowballing'!$AC$2:$AC$281,"Sin área SWEBOK") -> 0 | S15: =SUM(C15:R15) -> 0
B16: T011 Taxonomía | C16: =COUNTIFS('Prácticas_Revisiones'!$S$2:$S$282,"T011",'Prácticas_Revisiones'!$T$2:$T$282,"REQUIREMENTS > *")+COUNTIFS('Prácticas_Snowballing'!$AB$2:$AB$281,"T011",'Prácticas_Snowballing'!$AC$2:$AC$281,"REQUIREMENTS > *") -> 0 | D16: =COUNTIFS('Prácticas_Revisiones'!$S$2:$S$282,"T011",'Prácticas_Revisiones'!$T$2:$T$282,"ARCHITECTURE > *")+COUNTIFS('Prácticas_Snowballing'!$AB$2:$AB$281,"T011",'Prácticas_Snowballing'!$AC$2:$AC$281,"ARCHITECTURE > *") -> 0 | E16: =COUNTIFS('Prácticas_Revisiones'!$S$2:$S$282,"T011",'Prácticas_Revisiones'!$T$2:$T$282,"DESIGN > *")+COUNTIFS('Prácticas_Snowballing'!$AB$2:$AB$281,"T011",'Prácticas_Snowballing'!$AC$2:$AC$281,"DESIGN > *") -> 0 | F16: =COUNTIFS('Prácticas_Revisiones'!$S$2:$S$282,"T011",'Prácticas_Revisiones'!$T$2:$T$282,"CONSTRUCTION > *")+COUNTIFS('Prácticas_Snowballing'!$AB$2:$AB$281,"T011",'Prácticas_Snowballing'!$AC$2:$AC$281,"CONSTRUCTION > *") -> 0 | G16: =COUNTIFS('Prácticas_Revisiones'!$S$2:$S$282,"T011",'Prácticas_Revisiones'!$T$2:$T$282,"SOFTWARE TESTING > *")+COUNTIFS('Prácticas_Snowballing'!$AB$2:$AB$281,"T011",'Prácticas_Snowballing'!$AC$2:$AC$281,"SOFTWARE TESTING > *") -> 0 | H16: =COUNTIFS('Prácticas_Revisiones'!$S$2:$S$282,"T011",'Prácticas_Revisiones'!$T$2:$T$282,"SOFTWARE ENG. OPERATIONS > *")+COUNTIFS('Prácticas_Snowballing'!$AB$2:$AB$281,"T011",'Prácticas_Snowballing'!$AC$2:$AC$281,"SOFTWARE ENG. OPERATIONS > *") -> 0 | I16: =COUNTIFS('Prácticas_Revisiones'!$S$2:$S$282,"T011",'Prácticas_Revisiones'!$T$2:$T$282,"MAINTENANCE > *")+COUNTIFS('Prácticas_Snowballing'!$AB$2:$AB$281,"T011",'Prácticas_Snowballing'!$AC$2:$AC$281,"MAINTENANCE > *") -> 0 | J16: =COUNTIFS('Prácticas_Revisiones'!$S$2:$S$282,"T011",'Prácticas_Revisiones'!$T$2:$T$282,"SOFTWARE CONFIG. MGMT. > *")+COUNTIFS('Prácticas_Snowballing'!$AB$2:$AB$281,"T011",'Prácticas_Snowballing'!$AC$2:$AC$281,"SOFTWARE CONFIG. MGMT. > *") -> 0 | K16: =COUNTIFS('Prácticas_Revisiones'!$S$2:$S$282,"T011",'Prácticas_Revisiones'!$T$2:$T$282,"SOFTWARE ENG. PROCESS > *")+COUNTIFS('Prácticas_Snowballing'!$AB$2:$AB$281,"T011",'Prácticas_Snowballing'!$AC$2:$AC$281,"SOFTWARE ENG. PROCESS > *") -> 0 | L16: =COUNTIFS('Prácticas_Revisiones'!$S$2:$S$282,"T011",'Prácticas_Revisiones'!$T$2:$T$282,"SOFTWARE ENG. MODELS/METH. > *")+COUNTIFS('Prácticas_Snowballing'!$AB$2:$AB$281,"T011",'Prácticas_Snowballing'!$AC$2:$AC$281,"SOFTWARE ENG. MODELS/METH. > *") -> 0 | M16: =COUNTIFS('Prácticas_Revisiones'!$S$2:$S$282,"T011",'Prácticas_Revisiones'!$T$2:$T$282,"SOFTWARE QUALITY > *")+COUNTIFS('Prácticas_Snowballing'!$AB$2:$AB$281,"T011",'Prácticas_Snowballing'!$AC$2:$AC$281,"SOFTWARE QUALITY > *") -> 0 | N16: =COUNTIFS('Prácticas_Revisiones'!$S$2:$S$282,"T011",'Prácticas_Revisiones'!$T$2:$T$282,"SOFTWARE SECURITY > *")+COUNTIFS('Prácticas_Snowballing'!$AB$2:$AB$281,"T011",'Prácticas_Snowballing'!$AC$2:$AC$281,"SOFTWARE SECURITY > *") -> 0 | O16: =COUNTIFS('Prácticas_Revisiones'!$S$2:$S$282,"T011",'Prácticas_Revisiones'!$T$2:$T$282,"PROFESSIONAL PRACTICE > *")+COUNTIFS('Prácticas_Snowballing'!$AB$2:$AB$281,"T011",'Prácticas_Snowballing'!$AC$2:$AC$281,"PROFESSIONAL PRACTICE > *") -> 0 | P16: =COUNTIFS('Prácticas_Revisiones'!$S$2:$S$282,"T011",'Prácticas_Revisiones'!$T$2:$T$282,"SOFTWARE ENG. ECONOMICS > *")+COUNTIFS('Prácticas_Snowballing'!$AB$2:$AB$281,"T011",'Prácticas_Snowballing'!$AC$2:$AC$281,"SOFTWARE ENG. ECONOMICS > *") -> 0 | Q16: =COUNTIFS('Prácticas_Revisiones'!$S$2:$S$282,"T011",'Prácticas_Revisiones'!$T$2:$T$282,"SOFTWARE ENG. MANAGEMENT > *")+COUNTIFS('Prácticas_Snowballing'!$AB$2:$AB$281,"T011",'Prácticas_Snowballing'!$AC$2:$AC$281,"SOFTWARE ENG. MANAGEMENT > *") -> 0 | R16: =COUNTIFS('Prácticas_Revisiones'!$S$2:$S$282,"T011",'Prácticas_Revisiones'!$T$2:$T$282,"Sin área SWEBOK")+COUNTIFS('Prácticas_Snowballing'!$AB$2:$AB$281,"T011",'Prácticas_Snowballing'!$AC$2:$AC$281,"Sin área SWEBOK") -> 0 | S16: =SUM(C16:R16) -> 0
B17: Sin equivalente en catálogo | C17: =COUNTIFS('Prácticas_Revisiones'!$S$2:$S$282,"Sin equivalente en catálogo (RECORDAR)",'Prácticas_Revisiones'!$T$2:$T$282,"REQUIREMENTS > *")+COUNTIFS('Prácticas_Snowballing'!$AB$2:$AB$281,"Sin equivalente en catálogo (RECORDAR)",'Prácticas_Snowballing'!$AC$2:$AC$281,"REQUIREMENTS > *") -> 0 | D17: =COUNTIFS('Prácticas_Revisiones'!$S$2:$S$282,"Sin equivalente en catálogo (RECORDAR)",'Prácticas_Revisiones'!$T$2:$T$282,"ARCHITECTURE > *")+COUNTIFS('Prácticas_Snowballing'!$AB$2:$AB$281,"Sin equivalente en catálogo (RECORDAR)",'Prácticas_Snowballing'!$AC$2:$AC$281,"ARCHITECTURE > *") -> 0 | E17: =COUNTIFS('Prácticas_Revisiones'!$S$2:$S$282,"Sin equivalente en catálogo (RECORDAR)",'Prácticas_Revisiones'!$T$2:$T$282,"DESIGN > *")+COUNTIFS('Prácticas_Snowballing'!$AB$2:$AB$281,"Sin equivalente en catálogo (RECORDAR)",'Prácticas_Snowballing'!$AC$2:$AC$281,"DESIGN > *") -> 0 | F17: =COUNTIFS('Prácticas_Revisiones'!$S$2:$S$282,"Sin equivalente en catálogo (RECORDAR)",'Prácticas_Revisiones'!$T$2:$T$282,"CONSTRUCTION > *")+COUNTIFS('Prácticas_Snowballing'!$AB$2:$AB$281,"Sin equivalente en catálogo (RECORDAR)",'Prácticas_Snowballing'!$AC$2:$AC$281,"CONSTRUCTION > *") -> 0 | G17: =COUNTIFS('Prácticas_Revisiones'!$S$2:$S$282,"Sin equivalente en catálogo (RECORDAR)",'Prácticas_Revisiones'!$T$2:$T$282,"SOFTWARE TESTING > *")+COUNTIFS('Prácticas_Snowballing'!$AB$2:$AB$281,"Sin equivalente en catálogo (RECORDAR)",'Prácticas_Snowballing'!$AC$2:$AC$281,"SOFTWARE TESTING > *") -> 0 | H17: =COUNTIFS('Prácticas_Revisiones'!$S$2:$S$282,"Sin equivalente en catálogo (RECORDAR)",'Prácticas_Revisiones'!$T$2:$T$282,"SOFTWARE ENG. OPERATIONS > *")+COUNTIFS('Prácticas_Snowballing'!$AB$2:$AB$281,"Sin equivalente en catálogo (RECORDAR)",'Prácticas_Snowballing'!$AC$2:$AC$281,"SOFTWARE ENG. OPERATIONS > *") -> 0 | I17: =COUNTIFS('Prácticas_Revisiones'!$S$2:$S$282,"Sin equivalente en catálogo (RECORDAR)",'Prácticas_Revisiones'!$T$2:$T$282,"MAINTENANCE > *")+COUNTIFS('Prácticas_Snowballing'!$AB$2:$AB$281,"Sin equivalente en catálogo (RECORDAR)",'Prácticas_Snowballing'!$AC$2:$AC$281,"MAINTENANCE > *") -> 0 | J17: =COUNTIFS('Prácticas_Revisiones'!$S$2:$S$282,"Sin equivalente en catálogo (RECORDAR)",'Prácticas_Revisiones'!$T$2:$T$282,"SOFTWARE CONFIG. MGMT. > *")+COUNTIFS('Prácticas_Snowballing'!$AB$2:$AB$281,"Sin equivalente en catálogo (RECORDAR)",'Prácticas_Snowballing'!$AC$2:$AC$281,"SOFTWARE CONFIG. MGMT. > *") -> 0 | K17: =COUNTIFS('Prácticas_Revisiones'!$S$2:$S$282,"Sin equivalente en catálogo (RECORDAR)",'Prácticas_Revisiones'!$T$2:$T$282,"SOFTWARE ENG. PROCESS > *")+COUNTIFS('Prácticas_Snowballing'!$AB$2:$AB$281,"Sin equivalente en catálogo (RECORDAR)",'Prácticas_Snowballing'!$AC$2:$AC$281,"SOFTWARE ENG. PROCESS > *") -> 0 | L17: =COUNTIFS('Prácticas_Revisiones'!$S$2:$S$282,"Sin equivalente en catálogo (RECORDAR)",'Prácticas_Revisiones'!$T$2:$T$282,"SOFTWARE ENG. MODELS/METH. > *")+COUNTIFS('Prácticas_Snowballing'!$AB$2:$AB$281,"Sin equivalente en catálogo (RECORDAR)",'Prácticas_Snowballing'!$AC$2:$AC$281,"SOFTWARE ENG. MODELS/METH. > *") -> 0 | M17: =COUNTIFS('Prácticas_Revisiones'!$S$2:$S$282,"Sin equivalente en catálogo (RECORDAR)",'Prácticas_Revisiones'!$T$2:$T$282,"SOFTWARE QUALITY > *")+COUNTIFS('Prácticas_Snowballing'!$AB$2:$AB$281,"Sin equivalente en catálogo (RECORDAR)",'Prácticas_Snowballing'!$AC$2:$AC$281,"SOFTWARE QUALITY > *") -> 0 | N17: =COUNTIFS('Prácticas_Revisiones'!$S$2:$S$282,"Sin equivalente en catálogo (RECORDAR)",'Prácticas_Revisiones'!$T$2:$T$282,"SOFTWARE SECURITY > *")+COUNTIFS('Prácticas_Snowballing'!$AB$2:$AB$281,"Sin equivalente en catálogo (RECORDAR)",'Prácticas_Snowballing'!$AC$2:$AC$281,"SOFTWARE SECURITY > *") -> 0 | O17: =COUNTIFS('Prácticas_Revisiones'!$S$2:$S$282,"Sin equivalente en catálogo (RECORDAR)",'Prácticas_Revisiones'!$T$2:$T$282,"PROFESSIONAL PRACTICE > *")+COUNTIFS('Prácticas_Snowballing'!$AB$2:$AB$281,"Sin equivalente en catálogo (RECORDAR)",'Prácticas_Snowballing'!$AC$2:$AC$281,"PROFESSIONAL PRACTICE > *") -> 0 | P17: =COUNTIFS('Prácticas_Revisiones'!$S$2:$S$282,"Sin equivalente en catálogo (RECORDAR)",'Prácticas_Revisiones'!$T$2:$T$282,"SOFTWARE ENG. ECONOMICS > *")+COUNTIFS('Prácticas_Snowballing'!$AB$2:$AB$281,"Sin equivalente en catálogo (RECORDAR)",'Prácticas_Snowballing'!$AC$2:$AC$281,"SOFTWARE ENG. ECONOMICS > *") -> 0 | Q17: =COUNTIFS('Prácticas_Revisiones'!$S$2:$S$282,"Sin equivalente en catálogo (RECORDAR)",'Prácticas_Revisiones'!$T$2:$T$282,"SOFTWARE ENG. MANAGEMENT > *")+COUNTIFS('Prácticas_Snowballing'!$AB$2:$AB$281,"Sin equivalente en catálogo (RECORDAR)",'Prácticas_Snowballing'!$AC$2:$AC$281,"SOFTWARE ENG. MANAGEMENT > *") -> 0 | R17: =COUNTIFS('Prácticas_Revisiones'!$S$2:$S$282,"Sin equivalente en catálogo (RECORDAR)",'Prácticas_Revisiones'!$T$2:$T$282,"Sin área SWEBOK")+COUNTIFS('Prácticas_Snowballing'!$AB$2:$AB$281,"Sin equivalente en catálogo (RECORDAR)",'Prácticas_Snowballing'!$AC$2:$AC$281,"Sin área SWEBOK") -> 0 | S17: =SUM(C17:R17) -> 0
A18: Subtotal RECORDAR | C18: =SUM(C6:C17) -> 0 | D18: =SUM(D6:D17) -> 0 | E18: =SUM(E6:E17) -> 2 | F18: =SUM(F6:F17) -> 10 | G18: =SUM(G6:G17) -> 0 | H18: =SUM(H6:H17) -> 0 | I18: =SUM(I6:I17) -> 0 | J18: =SUM(J6:J17) -> 0 | ... S18: =SUM(S6:S17) -> 14
A19: EXPLICAR | B19: T012 Afiche | C19: =COUNTIFS('Prácticas_Revisiones'!$S$2:$S$282,"T012",'Prácticas_Revisiones'!$T$2:$T$282,"REQUIREMENTS > *")+COUNTIFS('Prácticas_Snowballing'!$AB$2:$AB$281,"T012",'Prácticas_Snowballing'!$AC$2:$AC$281,"REQUIREMENTS > *") -> 0 | D19: =COUNTIFS('Prácticas_Revisiones'!$S$2:$S$282,"T012",'Prácticas_Revisiones'!$T$2:$T$282,"ARCHITECTURE > *")+COUNTIFS('Prácticas_Snowballing'!$AB$2:$AB$281,"T012",'Prácticas_Snowballing'!$AC$2:$AC$281,"ARCHITECTURE > *") -> 0 | E19: =COUNTIFS('Prácticas_Revisiones'!$S$2:$S$282,"T012",'Prácticas_Revisiones'!$T$2:$T$282,"DESIGN > *")+COUNTIFS('Prácticas_Snowballing'!$AB$2:$AB$281,"T012",'Prácticas_Snowballing'!$AC$2:$AC$281,"DESIGN > *") -> 0 | F19: =COUNTIFS('Prácticas_Revisiones'!$S$2:$S$282,"T012",'Prácticas_Revisiones'!$T$2:$T$282,"CONSTRUCTION > *")+COUNTIFS('Prácticas_Snowballing'!$AB$2:$AB$281,"T012",'Prácticas_Snowballing'!$AC$2:$AC$281,"CONSTRUCTION > *") -> 0 | G19: =COUNTIFS('Prácticas_Revisiones'!$S$2:$S$282,"T012",'Prácticas_Revisiones'!$T$2:$T$282,"SOFTWARE TESTING > *")+COUNTIFS('Prácticas_Snowballing'!$AB$2:$AB$281,"T012",'Prácticas_Snowballing'!$AC$2:$AC$281,"SOFTWARE TESTING > *") -> 0 | H19: =COUNTIFS('Prácticas_Revisiones'!$S$2:$S$282,"T012",'Prácticas_Revisiones'!$T$2:$T$282,"SOFTWARE ENG. OPERATIONS > *")+COUNTIFS('Prácticas_Snowballing'!$AB$2:$AB$281,"T012",'Prácticas_Snowballing'!$AC$2:$AC$281,"SOFTWARE ENG. OPERATIONS > *") -> 0 | I19: =COUNTIFS('Prácticas_Revisiones'!$S$2:$S$282,"T012",'Prácticas_Revisiones'!$T$2:$T$282,"MAINTENANCE > *")+COUNTIFS('Prácticas_Snowballing'!$AB$2:$AB$281,"T012",'Prácticas_Snowballing'!$AC$2:$AC$281,"MAINTENANCE > *") -> 0 | J19: =COUNTIFS('Prácticas_Revisiones'!$S$2:$S$282,"T012",'Prácticas_Revisiones'!$T$2:$T$282,"SOFTWARE CONFIG. MGMT. > *")+COUNTIFS('Prácticas_Snowballing'!$AB$2:$AB$281,"T012",'Prácticas_Snowballing'!$AC$2:$AC$281,"SOFTWARE CONFIG. MGMT. > *") -> 0 | K19: =COUNTIFS('Prácticas_Revisiones'!$S$2:$S$282,"T012",'Prácticas_Revisiones'!$T$2:$T$282,"SOFTWARE ENG. PROCESS > *")+COUNTIFS('Prácticas_Snowballing'!$AB$2:$AB$281,"T012",'Prácticas_Snowballing'!$AC$2:$AC$281,"SOFTWARE ENG. PROCESS > *") -> 0 | L19: =COUNTIFS('Prácticas_Revisiones'!$S$2:$S$282,"T012",'Prácticas_Revisiones'!$T$2:$T$282,"SOFTWARE ENG. MODELS/METH. > *")+COUNTIFS('Prácticas_Snowballing'!$AB$2:$AB$281,"T012",'Prácticas_Snowballing'!$AC$2:$AC$281,"SOFTWARE ENG. MODELS/METH. > *") -> 0 | M19: =COUNTIFS('Prácticas_Revisiones'!$S$2:$S$282,"T012",'Prácticas_Revisiones'!$T$2:$T$282,"SOFTWARE QUALITY > *")+COUNTIFS('Prácticas_Snowballing'!$AB$2:$AB$281,"T012",'Prácticas_Snowballing'!$AC$2:$AC$281,"SOFTWARE QUALITY > *") -> 0 | N19: =COUNTIFS('Prácticas_Revisiones'!$S$2:$S$282,"T012",'Prácticas_Revisiones'!$T$2:$T$282,"SOFTWARE SECURITY > *")+COUNTIFS('Prácticas_Snowballing'!$AB$2:$AB$281,"T012",'Prácticas_Snowballing'!$AC$2:$AC$281,"SOFTWARE SECURITY > *") -> 0 | O19: =COUNTIFS('Prácticas_Revisiones'!$S$2:$S$282,"T012",'Prácticas_Revisiones'!$T$2:$T$282,"PROFESSIONAL PRACTICE > *")+COUNTIFS('Prácticas_Snowballing'!$AB$2:$AB$281,"T012",'Prácticas_Snowballing'!$AC$2:$AC$281,"PROFESSIONAL PRACTICE > *") -> 0 | P19: =COUNTIFS('Prácticas_Revisiones'!$S$2:$S$282,"T012",'Prácticas_Revisiones'!$T$2:$T$282,"SOFTWARE ENG. ECONOMICS > *")+COUNTIFS('Prácticas_Snowballing'!$AB$2:$AB$281,"T012",'Prácticas_Snowballing'!$AC$2:$AC$281,"SOFTWARE ENG. ECONOMICS > *") -> 0 | Q19: =COUNTIFS('Prácticas_Revisiones'!$S$2:$S$282,"T012",'Prácticas_Revisiones'!$T$2:$T$282,"SOFTWARE ENG. MANAGEMENT > *")+COUNTIFS('Prácticas_Snowballing'!$AB$2:$AB$281,"T012",'Prácticas_Snowballing'!$AC$2:$AC$281,"SOFTWARE ENG. MANAGEMENT > *") -> 0 | R19: =COUNTIFS('Prácticas_Revisiones'!$S$2:$S$282,"T012",'Prácticas_Revisiones'!$T$2:$T$282,"Sin área SWEBOK")+COUNTIFS('Prácticas_Snowballing'!$AB$2:$AB$281,"T012",'Prácticas_Snowballing'!$AC$2:$AC$281,"Sin área SWEBOK") -> 0 | S19: =SUM(C19:R19) -> 0
B20: T013 Anuncio publicitario | C20: =COUNTIFS('Prácticas_Revisiones'!$S$2:$S$282,"T013",'Prácticas_Revisiones'!$T$2:$T$282,"REQUIREMENTS > *")+COUNTIFS('Prácticas_Snowballing'!$AB$2:$AB$281,"T013",'Prácticas_Snowballing'!$AC$2:$AC$281,"REQUIREMENTS > *") -> 0 | D20: =COUNTIFS('Prácticas_Revisiones'!$S$2:$S$282,"T013",'Prácticas_Revisiones'!$T$2:$T$282,"ARCHITECTURE > *")+COUNTIFS('Prácticas_Snowballing'!$AB$2:$AB$281,"T013",'Prácticas_Snowballing'!$AC$2:$AC$281,"ARCHITECTURE > *") -> 0 | E20: =COUNTIFS('Prácticas_Revisiones'!$S$2:$S$282,"T013",'Prácticas_Revisiones'!$T$2:$T$282,"DESIGN > *")+COUNTIFS('Prácticas_Snowballing'!$AB$2:$AB$281,"T013",'Prácticas_Snowballing'!$AC$2:$AC$281,"DESIGN > *") -> 0 | F20: =COUNTIFS('Prácticas_Revisiones'!$S$2:$S$282,"T013",'Prácticas_Revisiones'!$T$2:$T$282,"CONSTRUCTION > *")+COUNTIFS('Prácticas_Snowballing'!$AB$2:$AB$281,"T013",'Prácticas_Snowballing'!$AC$2:$AC$281,"CONSTRUCTION > *") -> 0 | G20: =COUNTIFS('Prácticas_Revisiones'!$S$2:$S$282,"T013",'Prácticas_Revisiones'!$T$2:$T$282,"SOFTWARE TESTING > *")+COUNTIFS('Prácticas_Snowballing'!$AB$2:$AB$281,"T013",'Prácticas_Snowballing'!$AC$2:$AC$281,"SOFTWARE TESTING > *") -> 0 | H20: =COUNTIFS('Prácticas_Revisiones'!$S$2:$S$282,"T013",'Prácticas_Revisiones'!$T$2:$T$282,"SOFTWARE ENG. OPERATIONS > *")+COUNTIFS('Prácticas_Snowballing'!$AB$2:$AB$281,"T013",'Prácticas_Snowballing'!$AC$2:$AC$281,"SOFTWARE ENG. OPERATIONS > *") -> 0 | I20: =COUNTIFS('Prácticas_Revisiones'!$S$2:$S$282,"T013",'Prácticas_Revisiones'!$T$2:$T$282,"MAINTENANCE > *")+COUNTIFS('Prácticas_Snowballing'!$AB$2:$AB$281,"T013",'Prácticas_Snowballing'!$AC$2:$AC$281,"MAINTENANCE > *") -> 0 | J20: =COUNTIFS('Prácticas_Revisiones'!$S$2:$S$282,"T013",'Prácticas_Revisiones'!$T$2:$T$282,"SOFTWARE CONFIG. MGMT. > *")+COUNTIFS('Prácticas_Snowballing'!$AB$2:$AB$281,"T013",'Prácticas_Snowballing'!$AC$2:$AC$281,"SOFTWARE CONFIG. MGMT. > *") -> 0 | K20: =COUNTIFS('Prácticas_Revisiones'!$S$2:$S$282,"T013",'Prácticas_Revisiones'!$T$2:$T$282,"SOFTWARE ENG. PROCESS > *")+COUNTIFS('Prácticas_Snowballing'!$AB$2:$AB$281,"T013",'Prácticas_Snowballing'!$AC$2:$AC$281,"SOFTWARE ENG. PROCESS > *") -> 0 | L20: =COUNTIFS('Prácticas_Revisiones'!$S$2:$S$282,"T013",'Prácticas_Revisiones'!$T$2:$T$282,"SOFTWARE ENG. MODELS/METH. > *")+COUNTIFS('Prácticas_Snowballing'!$AB$2:$AB$281,"T013",'Prácticas_Snowballing'!$AC$2:$AC$281,"SOFTWARE ENG. MODELS/METH. > *") -> 0 | M20: =COUNTIFS('Prácticas_Revisiones'!$S$2:$S$282,"T013",'Prácticas_Revisiones'!$T$2:$T$282,"SOFTWARE QUALITY > *")+COUNTIFS('Prácticas_Snowballing'!$AB$2:$AB$281,"T013",'Prácticas_Snowballing'!$AC$2:$AC$281,"SOFTWARE QUALITY > *") -> 0 | N20: =COUNTIFS('Prácticas_Revisiones'!$S$2:$S$282,"T013",'Prácticas_Revisiones'!$T$2:$T$282,"SOFTWARE SECURITY > *")+COUNTIFS('Prácticas_Snowballing'!$AB$2:$AB$281,"T013",'Prácticas_Snowballing'!$AC$2:$AC$281,"SOFTWARE SECURITY > *") -> 0 | O20: =COUNTIFS('Prácticas_Revisiones'!$S$2:$S$282,"T013",'Prácticas_Revisiones'!$T$2:$T$282,"PROFESSIONAL PRACTICE > *")+COUNTIFS('Prácticas_Snowballing'!$AB$2:$AB$281,"T013",'Prácticas_Snowballing'!$AC$2:$AC$281,"PROFESSIONAL PRACTICE > *") -> 0 | P20: =COUNTIFS('Prácticas_Revisiones'!$S$2:$S$282,"T013",'Prácticas_Revisiones'!$T$2:$T$282,"SOFTWARE ENG. ECONOMICS > *")+COUNTIFS('Prácticas_Snowballing'!$AB$2:$AB$281,"T013",'Prácticas_Snowballing'!$AC$2:$AC$281,"SOFTWARE ENG. ECONOMICS > *") -> 0 | Q20: =COUNTIFS('Prácticas_Revisiones'!$S$2:$S$282,"T013",'Prácticas_Revisiones'!$T$2:$T$282,"SOFTWARE ENG. MANAGEMENT > *")+COUNTIFS('Prácticas_Snowballing'!$AB$2:$AB$281,"T013",'Prácticas_Snowballing'!$AC$2:$AC$281,"SOFTWARE ENG. MANAGEMENT > *") -> 0 | R20: =COUNTIFS('Prácticas_Revisiones'!$S$2:$S$282,"T013",'Prácticas_Revisiones'!$T$2:$T$282,"Sin área SWEBOK")+COUNTIFS('Prácticas_Snowballing'!$AB$2:$AB$281,"T013",'Prácticas_Snowballing'!$AC$2:$AC$281,"Sin área SWEBOK") -> 0 | S20: =SUM(C20:R20) -> 0
